<mujoco model="plane_and_cube">
    <compiler angle="radian" />
    <option gravity="0 0 -9.81" />
    <asset>
        <material name="floor" texture="checks1" texrepeat="5 5" texuniform="true"/>
        <texture name="checks1" builtin="checker" type="2d" width="256" height="256" rgb1="1 1 1" rgb2="0 0 0" /> 
        
        <material name="object" texture="checks2" texrepeat="5 5" texuniform="true"/>
        <texture name="checks2" builtin="checker" type="2d" width="256" height="256" rgb1="1 0 0" rgb2="0 1 0" /> 








    </asset>
    <!-- The world body -->
    <worldbody>
        <!-- Light source -->
        <light name="main_light" pos="0 0 1" dir="0 0 -1" diffuse="1 1 1" specular="0.1 0.1 0.1" />
        <!-- World frame -->
        <frame name="world_frame" pos="0 0 0" euler="0 0 0" />

        <!-- The ground plane -->
        <geom name="ground" type="plane" size="100 5 0.1" material="floor"/>

        <!-- The sppere -->
        <body name="sphere_body" pos="0 0 0.1">
            <geom name="sphere_geom" type="sphere" size="0.1" material="object" />
            <joint name="sphere_slide_1" type="slide" axis="1 0 0" />
            <joint name="sphere_slide_2" type="slide" axis="0 0 1"/>
            <joint name="sphere_hinge_1" type="hinge" axis="0 1 0"/>
        </body>

     
    </worldbody>

    <!-- Actuator and sensor definitions (optional) -->
    <actuator>
        <!-- Define any actuators here -->
    </actuator>

    <sensor>
        <!-- Define any sensors here -->
    </sensor>
</mujoco>
